<mujoco model="T170D">
    <compiler angle="radian" meshdir="../meshes/" />
    <asset>
        <mesh name="BASE_S" file="BASE_S.STL" />
        <mesh name="LEVEL_Y_S" file="LEVEL_Y_S.STL" />
        <mesh name="WAIST_R_S" file="WAIST_R_S.STL" />
        <mesh name="WAIST_Y_S" file="WAIST_Y_S.STL" />
        <mesh name="WAIST_P_S" file="WAIST_P_S.STL" />
        <mesh name="NECK_Y_S" file="NECK_Y_S.STL" />
        <mesh name="NECK_P_S" file="NECK_P_S.STL" />
        <mesh name="NECK_R_S" file="NECK_R_S.STL" />
        <mesh name="L_SHOULDER_P_S" file="L_SHOULDER_P_S.STL" />
        <mesh name="L_SHOULDER_R_S" file="L_SHOULDER_R_S.STL" />
        <mesh name="L_SHOULDER_Y_S" file="L_SHOULDER_Y_S.STL" />
        <mesh name="L_ELBOW_Y_S" file="L_ELBOW_Y_S.STL" />
        <mesh name="L_WRIST_P_S" file="L_WRIST_P_S.STL" />
        <mesh name="L_WRIST_Y_S" file="L_WRIST_Y_S.STL" />
        <mesh name="L_WRIST_R_S" file="L_WRIST_R_S.STL" />
        <mesh name="R_SHOULDER_P_S" file="R_SHOULDER_P_S.STL" />
        <mesh name="R_SHOULDER_R_S" file="R_SHOULDER_R_S.STL" />
        <mesh name="R_SHOULDER_Y_S" file="R_SHOULDER_Y_S.STL" />
        <mesh name="R_ELBOW_Y_S" file="R_ELBOW_Y_S.STL" />
        <mesh name="R_WRIST_P_S" file="R_WRIST_P_S.STL" />
        <mesh name="R_WRIST_Y_S" file="R_WRIST_Y_S.STL" />
        <mesh name="R_WRIST_R_S" file="R_WRIST_R_S.STL" />
        <texture type="skybox" builtin="gradient" rgb1="0.3 0.5 0.7" rgb2="0 0 0" width="512"
            height="512" />
        <texture name="texplane" type="2d" builtin="checker" rgb1=".2 .3 .4" rgb2=".1 0.15 0.2"
            width="512" height="512" mark="cross" markrgb=".8 .8 .8" />
        <material name="matplane" reflectance="0.3" texture="texplane" texrepeat="1 1"
            texuniform="true" />
    </asset>

    <worldbody>
        <light directional="true" diffuse=".4 .4 .4" specular="0.1 0.1 0.1" pos="0 0 5.0"
            dir="0 0 -1" castshadow="false" />
        <light directional="true" diffuse=".6 .6 .6" specular="0.2 0.2 0.2" pos="0 0 4" dir="0 0 -1" />

        <geom name="floor" pos="0 0 0" size="15 15 1" type="plane" material="matplane"
            margin="0.001" condim="3" friction="1 0.005 0.0001" />
        <geom type="mesh" contype="0" conaffinity="0" group="1" density="0" rgba="1 1 1 1"
            mesh="BASE_S" />
        <geom type="mesh" rgba="1 1 1 1" mesh="BASE_S" />
        <camera name="rgb_camera" pos="0 0 2" euler="0 0 0" fovy="60" />
        <body name="LEVEL_Y_S" pos="0 0 0.1279">
            <inertial pos="-0.072607 -0.0001 0.41852" quat="0 0.903587 0 0.428405" mass="2.04896"
                diaginertia="0.00729896 0.00692801 0.00197492" />
            <joint name="LEVEL_Y" pos="0 0 0" axis="0 0 1" type="slide" range="0 0.143"
                damping="0.1" armature='0.01'
            />
            <geom type="mesh" contype="0" conaffinity="0" group="1" density="0"
                rgba="0.776471 0.756863 0.737255 1" mesh="LEVEL_Y_S" />
            <geom type="mesh" rgba="0.776471 0.756863 0.737255 1" mesh="LEVEL_Y_S" />
            <body name="WAIST_R_S" pos="-0.0652 -0.0001 0.441589">
                <inertial pos="0.050437 1.2e-05 -0.053248"
                    quat="0.70698 -0.0139134 -0.0140774 0.706957" mass="1.24342"
                    diaginertia="0.0248777 0.024704 0.0011252" />
                <joint name="WAIST_R" pos="0 0 0" axis="-1 0 0" range="-0.3491 0.4363" damping="0.1"
                    armature='0.01'
                />
                <geom type="mesh" contype="0" conaffinity="0" group="1" density="0"
                    rgba="0.792157 0.819608 0.933333 1" mesh="WAIST_R_S" />
                <geom type="mesh" rgba="0.792157 0.819608 0.933333 1" mesh="WAIST_R_S" />
                <body name="WAIST_Y_S" pos="0.053 0 0.0318">
                    <inertial pos="3.7e-05 0.006415 0.050441"
                        quat="0.725933 -0.0786278 0.0733347 0.679309" mass="1.23332"
                        diaginertia="0.00107742 0.00104452 0.000864602" />
                    <joint name="WAIST_Y" pos="0 0 0" axis="0 0 -1" range="-1.309 1.309"
                        damping="0.1" armature='0.01'
                    />
                    <geom type="mesh" contype="0" conaffinity="0" group="1" density="0"
                        rgba="0.776471 0.756863 0.737255 1" mesh="WAIST_Y_S" />
                    <geom type="mesh" rgba="0.776471 0.756863 0.737255 1" mesh="WAIST_Y_S" />
                    <body name="WAIST_P_S" pos="0 0.0474 0.0552">
                        <inertial pos="-0.007893 -0.046793 0.195627"
                            quat="0.999303 0.0125559 0.0350207 -0.00309692" mass="4.10226"
                            diaginertia="0.0499969 0.0404734 0.0229972" />
                        <joint name="WAIST_P" pos="0 0 0" axis="0 -1 0" range="-0.17453 0.17453"
                            damping="0.1" armature='0.01'
                        />
                        <geom type="mesh" contype="0" conaffinity="0" group="1" density="0"
                            rgba="1 1 1 1" mesh="WAIST_P_S" />
                        <geom type="mesh" rgba="1 1 1 1" mesh="WAIST_P_S" />
                        <body name="NECK_Y_S" pos="0 -0.0474 0.2958">
                            <inertial pos="0 -0.016557 0.039095"
                                quat="0.959377 0.282126 5.09518e-07 -1.73263e-06" mass="0.346435"
                                diaginertia="0.000307454 0.000270441 0.000134958" />
                            <joint name="NECK_Y" pos="0 0 0" axis="0 0 1" range="-1.5708 1.5708"
                                damping="0.1" armature='0.01'
                            />
                            <geom type="mesh" contype="0" conaffinity="0" group="1" density="0"
                                rgba="0.866667 0.866667 0.890196 1" mesh="NECK_Y_S" />
                            <geom type="mesh" rgba="0.866667 0.866667 0.890196 1" mesh="NECK_Y_S" />
                            <body name="NECK_P_S" pos="0 -0.037 0.0372">
                                <inertial pos="1.4e-05 0.03233 0.045"
                                    quat="0.101682 0.699758 -0.101682 0.699758" mass="0.246086"
                                    diaginertia="0.000109592 9.05162e-05 6.63735e-05" />
                                <joint name="NECK_P" pos="0 0 0" axis="0 -1 0" damping="0.1"
                                    armature='0.01'
                                    range="-0.6981 0.5236" />
                                <geom type="mesh" contype="0" conaffinity="0" group="1" density="0"
                                    rgba="0.647059 0.619608 0.588235 1" mesh="NECK_P_S" />
                                <geom type="mesh" rgba="0.647059 0.619608 0.588235 1"
                                    mesh="NECK_P_S" />
                                <body name="NECK_R_S" pos="0.026 0.037 0.045">
                                    <inertial pos="-0.020617 0.00012 0.081576"
                                        quat="0.707146 -0.022404 -0.0238661 0.70631" mass="0.584219"
                                        diaginertia="0.00443631 0.00434778 0.00229841" />
                                    <joint name="NECK_R" pos="0 0 0" axis="1 0 0" damping="0.1"
                                        armature='0.01'
                                        range="-0.2618 0.2618" />
                                    <geom type="mesh" contype="0" conaffinity="0" group="1"
                                        density="0" rgba="1 1 1 1" mesh="NECK_R_S" />
                                    <geom type="mesh" rgba="1 1 1 1" mesh="NECK_R_S" />
                                </body>
                            </body>
                        </body>
                        <body name="L_SHOULDER_P_S" pos="0 0.06045 0.262">
                            <inertial pos="-0.003115 0.05959 1.3e-05"
                                quat="0.461356 0.54573 -0.448896 0.53649" mass="0.799013"
                                diaginertia="0.00063749 0.000622119 0.000541014" />
                            <joint name="L_SHOULDER_P" pos="0 0 0" axis="0 1 0" damping="0.1"
                                armature='0.01'
                                range="-3.1416 3.1416" />
                            <geom type="mesh" contype="0" conaffinity="0" group="1" density="0"
                                rgba="0.890196 0.890196 0.913725 1" mesh="L_SHOULDER_P_S" />
                            <geom type="mesh" rgba="0.890196 0.890196 0.913725 1"
                                mesh="L_SHOULDER_P_S" />
                            <body name="L_SHOULDER_R_S" pos="0.03135 0.06315 0">
                                <inertial pos="-0.030425 0.090877 0.000135"
                                    quat="0.475645 0.523308 -0.47627 0.522568" mass="0.674864"
                                    diaginertia="0.00124077 0.00111907 0.000560403" />
                                <joint name="L_SHOULDER_R" pos="0 0 0" axis="1 0 0" damping="0.1"
                                    armature='0.01'
                                    range="-1.396 0.5236" />
                                <geom type="mesh" contype="0" conaffinity="0" group="1" density="0"
                                    rgba="1 1 1 1" mesh="L_SHOULDER_R_S" />
                                <geom type="mesh" rgba="1 1 1 1" mesh="L_SHOULDER_R_S" />
                                <body name="L_SHOULDER_Y_S" pos="-0.03135 0.1423 0">
                                    <inertial pos="-0.000963 0.098022 7.2e-05"
                                        quat="0.494313 0.508575 -0.490866 0.50602" mass="0.602086"
                                        diaginertia="0.00100059 0.000993603 0.000316243" />
                                    <joint name="L_SHOULDER_Y" pos="0 0 0" axis="0 -1 0"
                                        damping="0.1" armature='0.01'
                                        range="-3.1416 3.1416" />
                                    <geom type="mesh" contype="0" conaffinity="0" group="1"
                                        density="0" rgba="1 1 1 1" mesh="L_SHOULDER_Y_S" />
                                    <geom type="mesh" rgba="1 1 1 1" mesh="L_SHOULDER_Y_S" />
                                    <body name="L_ELBOW_Y_S" pos="0.0294 0.1177 0">
                                        <inertial pos="-0.028116 0.063323 -1.6e-05"
                                            quat="0.48067 0.542203 -0.41966 0.546678" mass="0.43436"
                                            diaginertia="0.000453275 0.000409235 0.000259274" />
                                        <joint name="L_ELBOW_Y" pos="0 0 0" axis="-1 0 0"
                                            damping="0.1" armature='0.01'
                                            range="0 2.0071" />
                                        <geom type="mesh" contype="0" conaffinity="0" group="1"
                                            density="0" rgba="1 1 1 1" mesh="L_ELBOW_Y_S" />
                                        <geom type="mesh" rgba="1 1 1 1" mesh="L_ELBOW_Y_S" />
                                        <body name="L_WRIST_P_S" pos="-0.0294 0.103295 -0.000967978">
                                            <inertial pos="-0.000413 0.060067 0.020169"
                                                quat="0.625337 0.780308 -0.0046751 0.00723572"
                                                mass="0.532538"
                                                diaginertia="0.00133466 0.00128259 0.000271828" />
                                            <joint name="L_WRIST_P" pos="0 0 0" damping="0.1"
                                                armature='0.01'
                                                axis="0 0.999956 -0.00937055" range="-3.1416 3.1416"
                                            />
                                            <geom type="mesh" contype="0" conaffinity="0" group="1"
                                                density="0" rgba="1 1 1 1" mesh="L_WRIST_P_S" />
                                            <geom type="mesh" rgba="1 1 1 1" mesh="L_WRIST_P_S" />
                                            <body name="L_WRIST_Y_S"
                                                pos="-0.000557829 0.145954 0.0263779">
                                                <inertial pos="0.000478 -0.000216 -0.023074"
                                                    quat="0.568637 0.411309 0.423069 0.57314"
                                                    mass="0.246086"
                                                    diaginertia="0.000109592 9.05162e-05 6.63735e-05" />
                                                <joint name="L_WRIST_Y" pos="0 0 0" damping="0.1"
                                                    armature='0.01'
                                                    axis="0.0201019 -0.00936865 -0.999754"
                                                    range="-1.3963 1.3963"
                                                />
                                                <geom type="mesh" contype="0" conaffinity="0"
                                                    group="1" density="0"
                                                    rgba="0.792157 0.819608 0.933333 1"
                                                    mesh="L_WRIST_Y_S" />
                                                <geom type="mesh"
                                                    rgba="0.792157 0.819608 0.933333 1"
                                                    mesh="L_WRIST_Y_S" />
                                                <body name="L_WRIST_R_S"
                                                    pos="0.0265497 0.00013375 -0.0272242">
                                                    <inertial pos="-0.017402 0.13607 -0.000547"
                                                        quat="0.553606 0.58479 -0.408039 0.430169"
                                                        mass="0.52948"
                                                        diaginertia="0.00149874 0.00119905 0.000396604" />
                                                    <joint name="L_WRIST_R" pos="0 0 0"
                                                        damping="0.1" armature='0.01'
                                                        axis="0.999686 0.0151435 0.0199587"
                                                        range="-1.5533 0.0873"
                                                    />
                                                    <geom type="mesh" contype="0" conaffinity="0"
                                                        group="1" density="0"
                                                        rgba="0.890196 0.890196 0.913725 1"
                                                        mesh="L_WRIST_R_S" />
                                                    <geom type="mesh"
                                                        rgba="0.890196 0.890196 0.913725 1"
                                                        mesh="L_WRIST_R_S" />
                                                </body>
                                            </body>
                                        </body>
                                    </body>
                                </body>
                            </body>
                        </body>
                        <body name="R_SHOULDER_P_S" pos="0 -0.15525 0.262">
                            <inertial pos="-0.003115 -0.059657 1e-05"
                                quat="0.550635 0.453777 -0.540854 0.445381" mass="0.799013"
                                diaginertia="0.000637865 0.000623149 0.000540362" />
                            <joint name="R_SHOULDER_P" pos="0 0 0" axis="0 -1 0" damping="0.1"
                                armature='0.01'
                                range="-3.1416 3.1416" />
                            <geom type="mesh" contype="0" conaffinity="0" group="1" density="0"
                                rgba="0.890196 0.890196 0.913725 1" mesh="R_SHOULDER_P_S" />
                            <geom type="mesh" rgba="0.890196 0.890196 0.913725 1"
                                mesh="R_SHOULDER_P_S" />
                            <body name="R_SHOULDER_R_S" pos="0.03135 -0.06315 0">
                                <inertial pos="-0.030424 -0.09088 0.000136"
                                    quat="0.52334 0.475686 -0.522518 0.476248" mass="0.674839"
                                    diaginertia="0.00124051 0.00111888 0.000560347" />
                                <joint name="R_SHOULDER_R" pos="0 0 0" axis="1 0 0" damping="0.1"
                                    armature='0.01'
                                    range="-0.5236 1.396" />
                                <geom type="mesh" contype="0" conaffinity="0" group="1" density="0"
                                    rgba="0.890196 0.890196 0.913725 1" mesh="R_SHOULDER_R_S" />
                                <geom type="mesh" rgba="0.890196 0.890196 0.913725 1"
                                    mesh="R_SHOULDER_R_S" />
                                <body name="R_SHOULDER_Y_S" pos="-0.03135 -0.1423 0">
                                    <inertial pos="-0.000963 -0.098022 7.2e-05"
                                        quat="0.508189 0.493911 -0.506412 0.491266" mass="0.60208"
                                        diaginertia="0.00100054 0.000993555 0.000316234" />
                                    <joint name="R_SHOULDER_Y" pos="0 0 0" axis="0 1 0"
                                        damping="0.1" armature='0.01'
                                        range="-3.1416 3.1416" />
                                    <geom type="mesh" contype="0" conaffinity="0" group="1"
                                        density="0" rgba="1 1 1 1" mesh="R_SHOULDER_Y_S" />
                                    <geom type="mesh" rgba="1 1 1 1" mesh="R_SHOULDER_Y_S" />
                                    <body name="R_ELBOW_Y_S" pos="0.0294 -0.1177 0">
                                        <inertial pos="-0.028121 -0.063324 0.000539"
                                            quat="0.54545 0.478475 -0.543549 0.422019"
                                            mass="0.434281"
                                            diaginertia="0.000453206 0.000409157 0.00025927" />
                                        <joint name="R_ELBOW_Y" pos="0 0 0" axis="1 0 0"
                                            damping="0.1" armature='0.01'
                                            range="0 2.007" />
                                        <geom type="mesh" contype="0" conaffinity="0" group="1"
                                            density="0" rgba="0.890196 0.890196 0.913725 1"
                                            mesh="R_ELBOW_Y_S" />
                                        <geom type="mesh" rgba="0.890196 0.890196 0.913725 1"
                                            mesh="R_ELBOW_Y_S" />
                                        <body name="R_WRIST_P_S" pos="-0.0294 -0.1033 0">
                                            <inertial pos="4e-06 -0.05988 0.020736"
                                                quat="0.783268 0.621682 -0.000869096 0.00145396"
                                                mass="0.532564"
                                                diaginertia="0.0013348 0.00128278 0.000271882" />
                                            <joint name="R_WRIST_P" pos="0 0 0" axis="0 -1 0"
                                                damping="0.1" armature='0.01'
                                                range="-3.1416 3.1416" />
                                            <geom type="mesh" contype="0" conaffinity="0" group="1"
                                                density="0" rgba="1 1 1 1" mesh="R_WRIST_P_S" />
                                            <geom type="mesh" rgba="1 1 1 1" mesh="R_WRIST_P_S" />
                                            <body name="R_WRIST_Y_S" pos="0 -0.1457 0.02775">
                                                <inertial pos="1.4e-05 0 -0.02308"
                                                    quat="0.566703 0.422903 0.422903 0.566703"
                                                    mass="0.246086"
                                                    diaginertia="0.000109592 9.05162e-05 6.63735e-05" />
                                                <joint name="R_WRIST_Y" pos="0 0 0" axis="0 0 -1"
                                                    damping="0.1" armature='0.01'
                                                    range="-1.3963 1.3963"
                                                />
                                                <geom type="mesh" contype="0" conaffinity="0"
                                                    group="1" density="0"
                                                    rgba="0.792157 0.819608 0.933333 1"
                                                    mesh="R_WRIST_Y_S" />
                                                <geom type="mesh"
                                                    rgba="0.792157 0.819608 0.933333 1"
                                                    mesh="R_WRIST_Y_S" />
                                                <body name="R_WRIST_R_S" pos="0.026 0 -0.02775">
                                                    <inertial pos="-0.015482 -0.14218 -0.003437"
                                                        quat="0.572927 0.560445 -0.430876 0.414732"
                                                        mass="0.535023"
                                                        diaginertia="0.00167656 0.0013561 0.000438356" />
                                                    <joint name="R_WRIST_R" pos="0 0 0" axis="1 0 0"
                                                        damping="0.1" armature='0.01'
                                                        range="-0.0873 1.5533"
                                                    />
                                                    <geom type="mesh" contype="0" conaffinity="0"
                                                        group="1" density="0"
                                                        rgba="0.890196 0.890196 0.913725 1"
                                                        mesh="R_WRIST_R_S" />
                                                    <geom type="mesh"
                                                        rgba="0.890196 0.890196 0.913725 1"
                                                        mesh="R_WRIST_R_S" />
                                                </body>
                                            </body>
                                        </body>
                                    </body>
                                </body>
                            </body>
                        </body>
                    </body>
                </body>
            </body>
        </body>
    </worldbody>

    <actuator>
        <!-- 通用 PD 控制器（位置控制） -->
        <position name="LEVEL_Y_ctrl" joint="LEVEL_Y" ctrlrange="0 0.143" kp="1000" kv="100"
        />
        <position name="WAIST_R_ctrl" joint="WAIST_R" ctrlrange="-0.3491 0.4363" kp="1000" kv="100"
        />
        <position name="WAIST_Y_ctrl" joint="WAIST_Y" ctrlrange="-1.309 1.309" kp="1000" kv="100"
        />
        <position name="WAIST_P_ctrl" joint="WAIST_P" ctrlrange="-0.17453 0.17453" kp="1000"
            kv="100"
        />

        <!-- 颈部关节 -->
        <position name="NECK_Y_ctrl" joint="NECK_Y" ctrlrange="-1.5708 1.5708" kp="200" kv="10"
        />
        <position name="NECK_P_ctrl" joint="NECK_P" ctrlrange="-0.6981 0.5236" kp="200" kv="10"
        />
        <position name="NECK_R_ctrl" joint="NECK_R" ctrlrange="-0.2618 0.2618" kp="200" kv="10"
        />

        <!-- 左臂关节 -->
        <position name="L_SHOULDER_P_ctrl" joint="L_SHOULDER_P" ctrlrange="-3.1416 3.1416" kp="200"
            kv="10" />
        <position name="L_SHOULDER_R_ctrl" joint="L_SHOULDER_R" ctrlrange="-1.396 0.5236" kp="200"
            kv="10" />
        <position name="L_SHOULDER_Y_ctrl" joint="L_SHOULDER_Y" ctrlrange="-3.1416 3.1416" kp="200"
            kv="10" />
        <position name="L_ELBOW_Y_ctrl" joint="L_ELBOW_Y" ctrlrange="0 2.0071" kp="200" kv="10"
        />
        <position name="L_WRIST_P_ctrl" joint="L_WRIST_P" ctrlrange="-3.1416 3.1416" kp="200"
            kv="10" />
        <position name="L_WRIST_Y_ctrl" joint="L_WRIST_Y" ctrlrange="-1.3963 1.3963" kp="200"
            kv="10" />
        <position name="L_WRIST_R_ctrl" joint="L_WRIST_R" ctrlrange="-1.5533 0.0873" kp="200"
            kv="10" />

        <!-- 右臂关节 -->
        <position name="R_SHOULDER_P_ctrl" joint="R_SHOULDER_P" ctrlrange="-3.1416 3.1416" kp="200"
            kv="10" />
        <position name="R_SHOULDER_R_ctrl" joint="R_SHOULDER_R" ctrlrange="-0.5236 1.396" kp="200"
            kv="10" />
        <position name="R_SHOULDER_Y_ctrl" joint="R_SHOULDER_Y" ctrlrange="-3.1416 3.1416" kp="200"
            kv="10" />
        <position name="R_ELBOW_Y_ctrl" joint="R_ELBOW_Y" ctrlrange="0 2.007" kp="200" kv="10"
        />
        <position name="R_WRIST_P_ctrl" joint="R_WRIST_P" ctrlrange="-3.1416 3.1416" kp="200"
            kv="10" />
        <position name="R_WRIST_Y_ctrl" joint="R_WRIST_Y" ctrlrange="-1.3963 1.3963" kp="200"
            kv="10" />
        <position name="R_WRIST_R_ctrl" joint="R_WRIST_R" ctrlrange="-0.0873 1.5533" kp="200"
            kv="10" />
    </actuator>

</mujoco>