<?xml version="1.0" encoding="utf-8"?>
<!-- This URDF was automatically created by SolidWorks to URDF Exporter! Originally created by
Stephen Brawner (brawner@gmail.com) 
     Commit Version: 1.6.0-1-g15f4949  Build Version: 1.6.7594.29634
     For more information, please see http://wiki.ros.org/sw_urdf_exporter -->
<robot
  name="T1Pro-A7-L">
  <link
    name="base_link">
    <inertial>
      <origin
        xyz="-0.00093347987677767 0.000231426447448682 0.000282402277015465"
        rpy="0 0 0" />
      <mass
        value="0.00399395942936461" />
      <inertia
        ixx="7.70850226602783E-07"
        ixy="2.28447669781266E-09"
        ixz="-1.39924462244439E-08"
        iyy="8.38081895398985E-07"
        iyz="-5.65559870663779E-09"
        izz="1.59919170773199E-06" />
    </inertial>
    <visual>
      <origin
        xyz="0 0 0"
        rpy="0 0 0" />
      <geometry>
        <mesh
          filename="D:/code/mj_ArmControl/urdf/T1Pro-A7-DualArm/T1Pro-A7-L/meshes/base_link.STL" />
      </geometry>
      <material
        name="">
        <color
          rgba="0.792156862745098 0.819607843137255 0.933333333333333 1" />
      </material>
    </visual>
    <collision>
      <origin
        xyz="0 0 0"
        rpy="0 0 0" />
      <geometry>
        <mesh
          filename="D:/code/mj_ArmControl/urdf/T1Pro-A7-DualArm/T1Pro-A7-L/meshes/base_link.STL" />
      </geometry>
    </collision>
  </link>
  <link
    name="Link1_Link">
    <inertial>
      <origin
        xyz="-0.000252119288470309 -0.00243241362043456 0.0026873694418611"
        rpy="0 0 0" />
      <mass
        value="0.310291977156634" />
      <inertia
        ixx="0.000275828965660294"
        ixy="4.59783865698426E-07"
        ixz="2.22763661982139E-06"
        iyy="0.000327508090369342"
        iyz="-2.36501826096446E-05"
        izz="0.000207307787702761" />
    </inertial>
    <visual>
      <origin
        xyz="0 0 0"
        rpy="0 0 0" />
      <geometry>
        <mesh
          filename="D:/code/mj_ArmControl/urdf/T1Pro-A7-DualArm/T1Pro-A7-L/meshes/Link1_Link.STL" />
      </geometry>
      <material
        name="">
        <color
          rgba="0.568627450980392 0.596078431372549 0.623529411764706 1" />
      </material>
    </visual>
    <collision>
      <origin
        xyz="0 0 0"
        rpy="0 0 0" />
      <geometry>
        <mesh
          filename="D:/code/mj_ArmControl/urdf/T1Pro-A7-DualArm/T1Pro-A7-L/meshes/Link1_Link.STL" />
      </geometry>
    </collision>
  </link>
  <joint
    name="Joint1"
    type="continuous">
    <origin
      xyz="0 0 0.0518799983656614"
      rpy="3.14159265358979 0 -3.14159265358979" />
    <parent
      link="base_link" />
    <child
      link="Link1_Link" />
    <axis
      xyz="0 0 -1" />
  </joint>
  <link
    name="Link2_Link">
    <inertial>
      <origin
        xyz="0.0200454763728002 0.000771589182937854 0.000232555565279452"
        rpy="0 0 0" />
      <mass
        value="0.516204366712496" />
      <inertia
        ixx="0.000310662653479027"
        ixy="0.000159677989975968"
        ixz="-1.0517930530116E-05"
        iyy="0.000890161440791034"
        iyz="3.18376109389917E-06"
        izz="0.00096423905129916" />
    </inertial>
    <visual>
      <origin
        xyz="0 0 0"
        rpy="0 0 0" />
      <geometry>
        <mesh
          filename="D:/code/mj_ArmControl/urdf/T1Pro-A7-DualArm/T1Pro-A7-L/meshes/Link2_Link.STL" />
      </geometry>
      <material
        name="">
        <color
          rgba="0.568627450980392 0.596078431372549 0.623529411764706 1" />
      </material>
    </visual>
    <collision>
      <origin
        xyz="0 0 0"
        rpy="0 0 0" />
      <geometry>
        <mesh
          filename="D:/code/mj_ArmControl/urdf/T1Pro-A7-DualArm/T1Pro-A7-L/meshes/Link2_Link.STL" />
      </geometry>
    </collision>
  </link>
  <joint
    name="Joint2"
    type="continuous">
    <origin
      xyz="-0.000970143413927975 -0.0110000000000002 -0.0379999999999999"
      rpy="0 1.5707963267949 0" />
    <parent
      link="Link1_Link" />
    <child
      link="Link2_Link" />
    <axis
      xyz="0 0 -1" />
  </joint>
  <link
    name="Link3_Link">
    <inertial>
      <origin
        xyz="0.000729069742052387 -0.00126712101592633 -0.019092402835496"
        rpy="0 0 0" />
      <mass
        value="0.410286624371692" />
      <inertia
        ixx="0.000565117665556109"
        ixy="-4.15649213231623E-05"
        ixz="7.83009044901346E-06"
        iyy="0.000613046304712329"
        iyz="-1.33919860746722E-05"
        izz="0.000214237061483164" />
    </inertial>
    <visual>
      <origin
        xyz="0 0 0"
        rpy="0 0 0" />
      <geometry>
        <mesh
          filename="D:/code/mj_ArmControl/urdf/T1Pro-A7-DualArm/T1Pro-A7-L/meshes/Link3_Link.STL" />
      </geometry>
      <material
        name="">
        <color
          rgba="0.568627450980392 0.596078431372549 0.623529411764706 1" />
      </material>
    </visual>
    <collision>
      <origin
        xyz="0 0 0"
        rpy="0 0 0" />
      <geometry>
        <mesh
          filename="D:/code/mj_ArmControl/urdf/T1Pro-A7-DualArm/T1Pro-A7-L/meshes/Link3_Link.STL" />
      </geometry>
    </collision>
  </link>
  <joint
    name="Joint3"
    type="continuous">
    <origin
      xyz="0.156124430662511 -0.0411115898849441 0.00137014390910662"
      rpy="-1.5707963267949 0.935267996896458 1.2389190608436" />
    <parent
      link="Link2_Link" />
    <child
      link="Link3_Link" />
    <axis
      xyz="0 0 1" />
  </joint>
  <link
    name="Link4_Link">
    <inertial>
      <origin
        xyz="0.0185487904531895 -0.00186287366149751 0.00120466324727674"
        rpy="0 0 0" />
      <mass
        value="0.222372153695005" />
      <inertia
        ixx="0.000107466902914002"
        ixy="1.14277856673017E-05"
        ixz="-1.30842237173483E-06"
        iyy="0.000234681968070962"
        iyz="7.10312652854803E-07"
        izz="0.000235550865373618" />
    </inertial>
    <visual>
      <origin
        xyz="0 0 0"
        rpy="0 0 0" />
      <geometry>
        <mesh
          filename="D:/code/mj_ArmControl/urdf/T1Pro-A7-DualArm/T1Pro-A7-L/meshes/Link4_Link.STL" />
      </geometry>
      <material
        name="">
        <color
          rgba="0.698039215686274 0.698039215686274 0.698039215686274 1" />
      </material>
    </visual>
    <collision>
      <origin
        xyz="0 0 0"
        rpy="0 0 0" />
      <geometry>
        <mesh
          filename="D:/code/mj_ArmControl/urdf/T1Pro-A7-DualArm/T1Pro-A7-L/meshes/Link4_Link.STL" />
      </geometry>
    </collision>
  </link>
  <joint
    name="Joint4"
    type="continuous">
    <origin
      xyz="-0.00103923048454458 -0.000600000000002189 -0.0821"
      rpy="-0.745419476274158 1.57079631189374 -0.110657221173896" />
    <parent
      link="Link3_Link" />
    <child
      link="Link4_Link" />
    <axis
      xyz="0 0 1" />
  </joint>
  <link
    name="Link5_Link">
    <inertial>
      <origin
        xyz="0.000161474114949132 4.90225837905534E-06 -0.0572438195043213"
        rpy="0 0 0" />
      <mass
        value="0.571928102853348" />
      <inertia
        ixx="0.00126021712350382"
        ixy="-4.33731553018467E-07"
        ixz="-1.94150501357278E-06"
        iyy="0.00125902242769663"
        iyz="6.07831229123519E-05"
        izz="0.000223810239215527" />
    </inertial>
    <visual>
      <origin
        xyz="0 0 0"
        rpy="0 0 0" />
      <geometry>
        <mesh
          filename="D:/code/mj_ArmControl/urdf/T1Pro-A7-DualArm/T1Pro-A7-L/meshes/Link5_Link.STL" />
      </geometry>
      <material
        name="">
        <color
          rgba="0.568627450980392 0.596078431372549 0.623529411764706 1" />
      </material>
    </visual>
    <collision>
      <origin
        xyz="0 0 0"
        rpy="0 0 0" />
      <geometry>
        <mesh
          filename="D:/code/mj_ArmControl/urdf/T1Pro-A7-DualArm/T1Pro-A7-L/meshes/Link5_Link.STL" />
      </geometry>
    </collision>
  </link>
  <joint
    name="Joint5"
    type="continuous">
    <origin
      xyz="0.0920892355713894 -0.00870762262054131 0.00122644118367604"
      rpy="-1.85483345674634 -1.57079631189374 1.75951726128189" />
    <parent
      link="Link4_Link" />
    <child
      link="Link5_Link" />
    <axis
      xyz="0 0 -1" />
  </joint>
  <link
    name="Link6_Link">
    <inertial>
      <origin
        xyz="7.09360578721174E-07 -2.55426993445163E-09 8.64070509587478E-09"
        rpy="0 0 0" />
      <mass
        value="0.00610543755423291" />
      <inertia
        ixx="2.21213958699756E-07"
        ixy="-1.1059367670104E-17"
        ixz="1.36990107850647E-09"
        iyy="1.97024136807474E-07"
        iyz="-1.34765971457153E-19"
        izz="6.1595150473153E-08" />
    </inertial>
    <visual>
      <origin
        xyz="0 0 0"
        rpy="0 0 0" />
      <geometry>
        <mesh
          filename="D:/code/mj_ArmControl/urdf/T1Pro-A7-DualArm/T1Pro-A7-L/meshes/Link6_Link.STL" />
      </geometry>
      <material
        name="">
        <color
          rgba="0.615686274509804 0.643137254901961 0.674509803921569 1" />
      </material>
    </visual>
    <collision>
      <origin
        xyz="0 0 0"
        rpy="0 0 0" />
      <geometry>
        <mesh
          filename="D:/code/mj_ArmControl/urdf/T1Pro-A7-DualArm/T1Pro-A7-L/meshes/Link6_Link.STL" />
      </geometry>
    </collision>
  </link>
  <joint
    name="Joint6"
    type="continuous">
    <origin
      xyz="0 0 -0.15085000000211"
      rpy="-1.60339513219979 1.31334111372083 -3.13934567374073" />
    <parent
      link="Link5_Link" />
    <child
      link="Link6_Link" />
    <axis
      xyz="0 0 -1" />
  </joint>
  <link
    name="Link7_Link">
    <inertial>
      <origin
        xyz="2.12036770608215E-06 0.0122957406820937 -0.00226705563851505"
        rpy="0 0 0" />
      <mass
        value="0.0340574088084564" />
      <inertia
        ixx="6.25072003486715E-06"
        ixy="8.31908650767659E-10"
        ixz="4.68661586365165E-10"
        iyy="9.66329500196333E-06"
        iyz="-5.17641211795578E-07"
        izz="6.60152589560128E-06" />
    </inertial>
    <visual>
      <origin
        xyz="0 0 0"
        rpy="0 0 0" />
      <geometry>
        <mesh
          filename="D:/code/mj_ArmControl/urdf/T1Pro-A7-DualArm/T1Pro-A7-L/meshes/Link7_Link.STL" />
      </geometry>
      <material
        name="">
        <color
          rgba="0.890196078431373 0.890196078431373 0.913725490196078 1" />
      </material>
    </visual>
    <collision>
      <origin
        xyz="0 0 0"
        rpy="0 0 0" />
      <geometry>
        <mesh
          filename="D:/code/mj_ArmControl/urdf/T1Pro-A7-DualArm/T1Pro-A7-L/meshes/Link7_Link.STL" />
      </geometry>
    </collision>
  </link>
  <joint
    name="Joint7"
    type="continuous">
    <origin
      xyz="0 0 0"
      rpy="-2.88428701617851 -1.56853814954965 1.5707963267949" />
    <parent
      link="Link6_Link" />
    <child
      link="Link7_Link" />
    <axis
      xyz="-0.00225817532594474 -0.254475168058109 -0.967076671979008" />
  </joint>
</robot>